[2022-05-02 22:21:12,903] {taskinstance.py:1032} INFO - Dependencies all met for <TaskInstance: ETL.main scheduled__2022-05-02T18:00:00+00:00 [queued]>
[2022-05-02 22:21:13,018] {taskinstance.py:1032} INFO - Dependencies all met for <TaskInstance: ETL.main scheduled__2022-05-02T18:00:00+00:00 [queued]>
[2022-05-02 22:21:13,021] {taskinstance.py:1238} INFO - 
--------------------------------------------------------------------------------
[2022-05-02 22:21:13,022] {taskinstance.py:1239} INFO - Starting attempt 1 of 2
[2022-05-02 22:21:13,024] {taskinstance.py:1240} INFO - 
--------------------------------------------------------------------------------
[2022-05-02 22:21:13,075] {taskinstance.py:1259} INFO - Executing <Task(PythonOperator): main> on 2022-05-02 18:00:00+00:00
[2022-05-02 22:21:13,087] {standard_task_runner.py:52} INFO - Started process 489 to run task
[2022-05-02 22:21:13,098] {standard_task_runner.py:76} INFO - Running: ['***', 'tasks', 'run', 'ETL', 'main', 'scheduled__2022-05-02T18:00:00+00:00', '--job-id', '2', '--raw', '--subdir', 'DAGS_FOLDER/ETL.py', '--cfg-path', '/tmp/tmpqsyw32if', '--error-file', '/tmp/tmp0dzr04bx']
[2022-05-02 22:21:13,102] {standard_task_runner.py:77} INFO - Job 2: Subtask main
[2022-05-02 22:21:13,284] {logging_mixin.py:109} INFO - Running <TaskInstance: ETL.main scheduled__2022-05-02T18:00:00+00:00 [running]> on host 9f1b8837587a
[2022-05-02 22:21:13,466] {taskinstance.py:1426} INFO - Exporting the following env vars:
AIRFLOW_CTX_DAG_OWNER=***
AIRFLOW_CTX_DAG_ID=ETL
AIRFLOW_CTX_TASK_ID=main
AIRFLOW_CTX_EXECUTION_DATE=2022-05-02T18:00:00+00:00
AIRFLOW_CTX_DAG_RUN_ID=scheduled__2022-05-02T18:00:00+00:00
[2022-05-02 22:21:14,022] {logging_mixin.py:109} INFO - ['BTC/USD', '2022-05-02 22:21:13', 38957.7]
[2022-05-02 22:21:14,036] {logging_mixin.py:109} INFO - etl does not exist in the DB!
[2022-05-02 22:21:14,038] {taskinstance.py:1700} ERROR - Task failed with exception
Traceback (most recent call last):
  File "/home/airflow/.local/lib/python3.7/site-packages/airflow/models/taskinstance.py", line 1329, in _run_raw_task
    self._execute_task_with_callbacks(context)
  File "/home/airflow/.local/lib/python3.7/site-packages/airflow/models/taskinstance.py", line 1455, in _execute_task_with_callbacks
    result = self._execute_task(context, self.task)
  File "/home/airflow/.local/lib/python3.7/site-packages/airflow/models/taskinstance.py", line 1511, in _execute_task
    result = execute_callable(context=context)
  File "/home/airflow/.local/lib/python3.7/site-packages/airflow/operators/python.py", line 174, in execute
    return_value = self.execute_callable()
  File "/home/airflow/.local/lib/python3.7/site-packages/airflow/operators/python.py", line 185, in execute_callable
    return self.python_callable(*self.op_args, **self.op_kwargs)
  File "/opt/airflow/dags/ETL.py", line 71, in main
    check_table_exists("etl", engine)
  File "/opt/airflow/dags/ETL.py", line 30, in check_table_exists
    cursor = engine.cursor()
AttributeError: 'Engine' object has no attribute 'cursor'
[2022-05-02 22:21:14,087] {taskinstance.py:1277} INFO - Marking task as UP_FOR_RETRY. dag_id=ETL, task_id=main, execution_date=20220502T180000, start_date=20220502T222112, end_date=20220502T222114
[2022-05-02 22:21:14,148] {standard_task_runner.py:92} ERROR - Failed to execute job 2 for task main
Traceback (most recent call last):
  File "/home/airflow/.local/lib/python3.7/site-packages/airflow/task/task_runner/standard_task_runner.py", line 85, in _start_by_fork
    args.func(args, dag=self.dag)
  File "/home/airflow/.local/lib/python3.7/site-packages/airflow/cli/cli_parser.py", line 48, in command
    return func(*args, **kwargs)
  File "/home/airflow/.local/lib/python3.7/site-packages/airflow/utils/cli.py", line 92, in wrapper
    return f(*args, **kwargs)
  File "/home/airflow/.local/lib/python3.7/site-packages/airflow/cli/commands/task_command.py", line 298, in task_run
    _run_task_by_selected_method(args, dag, ti)
  File "/home/airflow/.local/lib/python3.7/site-packages/airflow/cli/commands/task_command.py", line 107, in _run_task_by_selected_method
    _run_raw_task(args, ti)
  File "/home/airflow/.local/lib/python3.7/site-packages/airflow/cli/commands/task_command.py", line 184, in _run_raw_task
    error_file=args.error_file,
  File "/home/airflow/.local/lib/python3.7/site-packages/airflow/utils/session.py", line 70, in wrapper
    return func(*args, session=session, **kwargs)
  File "/home/airflow/.local/lib/python3.7/site-packages/airflow/models/taskinstance.py", line 1329, in _run_raw_task
    self._execute_task_with_callbacks(context)
  File "/home/airflow/.local/lib/python3.7/site-packages/airflow/models/taskinstance.py", line 1455, in _execute_task_with_callbacks
    result = self._execute_task(context, self.task)
  File "/home/airflow/.local/lib/python3.7/site-packages/airflow/models/taskinstance.py", line 1511, in _execute_task
    result = execute_callable(context=context)
  File "/home/airflow/.local/lib/python3.7/site-packages/airflow/operators/python.py", line 174, in execute
    return_value = self.execute_callable()
  File "/home/airflow/.local/lib/python3.7/site-packages/airflow/operators/python.py", line 185, in execute_callable
    return self.python_callable(*self.op_args, **self.op_kwargs)
  File "/opt/airflow/dags/ETL.py", line 71, in main
    check_table_exists("etl", engine)
  File "/opt/airflow/dags/ETL.py", line 30, in check_table_exists
    cursor = engine.cursor()
AttributeError: 'Engine' object has no attribute 'cursor'
[2022-05-02 22:21:14,189] {local_task_job.py:154} INFO - Task exited with return code 1
[2022-05-02 22:21:14,278] {local_task_job.py:264} INFO - 0 downstream tasks scheduled from follow-on schedule check
