[2022-05-02 22:29:26,798] {taskinstance.py:1032} INFO - Dependencies all met for <TaskInstance: ETL.main scheduled__2022-05-02T18:00:00+00:00 [queued]>
[2022-05-02 22:29:26,850] {taskinstance.py:1032} INFO - Dependencies all met for <TaskInstance: ETL.main scheduled__2022-05-02T18:00:00+00:00 [queued]>
[2022-05-02 22:29:26,852] {taskinstance.py:1238} INFO - 
--------------------------------------------------------------------------------
[2022-05-02 22:29:26,854] {taskinstance.py:1239} INFO - Starting attempt 4 of 5
[2022-05-02 22:29:26,856] {taskinstance.py:1240} INFO - 
--------------------------------------------------------------------------------
[2022-05-02 22:29:26,916] {taskinstance.py:1259} INFO - Executing <Task(PythonOperator): main> on 2022-05-02 18:00:00+00:00
[2022-05-02 22:29:26,933] {standard_task_runner.py:52} INFO - Started process 942 to run task
[2022-05-02 22:29:26,966] {standard_task_runner.py:76} INFO - Running: ['***', 'tasks', 'run', 'ETL', 'main', 'scheduled__2022-05-02T18:00:00+00:00', '--job-id', '5', '--raw', '--subdir', 'DAGS_FOLDER/ETL.py', '--cfg-path', '/tmp/tmpcyfz70ur', '--error-file', '/tmp/tmpbykwxr6a']
[2022-05-02 22:29:26,972] {standard_task_runner.py:77} INFO - Job 5: Subtask main
[2022-05-02 22:29:27,130] {logging_mixin.py:109} INFO - Running <TaskInstance: ETL.main scheduled__2022-05-02T18:00:00+00:00 [running]> on host 9f1b8837587a
[2022-05-02 22:29:27,300] {taskinstance.py:1426} INFO - Exporting the following env vars:
AIRFLOW_CTX_DAG_OWNER=***
AIRFLOW_CTX_DAG_ID=ETL
AIRFLOW_CTX_TASK_ID=main
AIRFLOW_CTX_EXECUTION_DATE=2022-05-02T18:00:00+00:00
AIRFLOW_CTX_DAG_RUN_ID=scheduled__2022-05-02T18:00:00+00:00
[2022-05-02 22:29:27,672] {logging_mixin.py:109} INFO - ['BTC/USD', '2022-05-02 22:29:27', 38957.7]
[2022-05-02 22:29:27,681] {logging_mixin.py:109} INFO - etl does not exist in the DB!
[2022-05-02 22:29:27,683] {taskinstance.py:1700} ERROR - Task failed with exception
Traceback (most recent call last):
  File "/home/airflow/.local/lib/python3.7/site-packages/airflow/models/taskinstance.py", line 1329, in _run_raw_task
    self._execute_task_with_callbacks(context)
  File "/home/airflow/.local/lib/python3.7/site-packages/airflow/models/taskinstance.py", line 1455, in _execute_task_with_callbacks
    result = self._execute_task(context, self.task)
  File "/home/airflow/.local/lib/python3.7/site-packages/airflow/models/taskinstance.py", line 1511, in _execute_task
    result = execute_callable(context=context)
  File "/home/airflow/.local/lib/python3.7/site-packages/airflow/operators/python.py", line 174, in execute
    return_value = self.execute_callable()
  File "/home/airflow/.local/lib/python3.7/site-packages/airflow/operators/python.py", line 185, in execute_callable
    return self.python_callable(*self.op_args, **self.op_kwargs)
  File "/opt/airflow/dags/ETL.py", line 65, in main
    check_table_exists("etl", engine)
  File "/opt/airflow/dags/ETL.py", line 27, in check_table_exists
    pd.read_sql(f"CREATE TABLE currnecy.""{table_name}"" (currency_pair VARCHAR NOT NULL,    created_on TIMESTAMP NOT NULL, current_rate decimal not null );")
TypeError: read_sql() missing 1 required positional argument: 'con'
[2022-05-02 22:29:27,741] {taskinstance.py:1277} INFO - Marking task as UP_FOR_RETRY. dag_id=ETL, task_id=main, execution_date=20220502T180000, start_date=20220502T222926, end_date=20220502T222927
[2022-05-02 22:29:27,794] {standard_task_runner.py:92} ERROR - Failed to execute job 5 for task main
Traceback (most recent call last):
  File "/home/airflow/.local/lib/python3.7/site-packages/airflow/task/task_runner/standard_task_runner.py", line 85, in _start_by_fork
    args.func(args, dag=self.dag)
  File "/home/airflow/.local/lib/python3.7/site-packages/airflow/cli/cli_parser.py", line 48, in command
    return func(*args, **kwargs)
  File "/home/airflow/.local/lib/python3.7/site-packages/airflow/utils/cli.py", line 92, in wrapper
    return f(*args, **kwargs)
  File "/home/airflow/.local/lib/python3.7/site-packages/airflow/cli/commands/task_command.py", line 298, in task_run
    _run_task_by_selected_method(args, dag, ti)
  File "/home/airflow/.local/lib/python3.7/site-packages/airflow/cli/commands/task_command.py", line 107, in _run_task_by_selected_method
    _run_raw_task(args, ti)
  File "/home/airflow/.local/lib/python3.7/site-packages/airflow/cli/commands/task_command.py", line 184, in _run_raw_task
    error_file=args.error_file,
  File "/home/airflow/.local/lib/python3.7/site-packages/airflow/utils/session.py", line 70, in wrapper
    return func(*args, session=session, **kwargs)
  File "/home/airflow/.local/lib/python3.7/site-packages/airflow/models/taskinstance.py", line 1329, in _run_raw_task
    self._execute_task_with_callbacks(context)
  File "/home/airflow/.local/lib/python3.7/site-packages/airflow/models/taskinstance.py", line 1455, in _execute_task_with_callbacks
    result = self._execute_task(context, self.task)
  File "/home/airflow/.local/lib/python3.7/site-packages/airflow/models/taskinstance.py", line 1511, in _execute_task
    result = execute_callable(context=context)
  File "/home/airflow/.local/lib/python3.7/site-packages/airflow/operators/python.py", line 174, in execute
    return_value = self.execute_callable()
  File "/home/airflow/.local/lib/python3.7/site-packages/airflow/operators/python.py", line 185, in execute_callable
    return self.python_callable(*self.op_args, **self.op_kwargs)
  File "/opt/airflow/dags/ETL.py", line 65, in main
    check_table_exists("etl", engine)
  File "/opt/airflow/dags/ETL.py", line 27, in check_table_exists
    pd.read_sql(f"CREATE TABLE currnecy.""{table_name}"" (currency_pair VARCHAR NOT NULL,    created_on TIMESTAMP NOT NULL, current_rate decimal not null );")
TypeError: read_sql() missing 1 required positional argument: 'con'
[2022-05-02 22:29:27,843] {local_task_job.py:154} INFO - Task exited with return code 1
[2022-05-02 22:29:27,929] {local_task_job.py:264} INFO - 0 downstream tasks scheduled from follow-on schedule check
