[2022-05-02 22:30:29,230] {taskinstance.py:1032} INFO - Dependencies all met for <TaskInstance: ETL.main scheduled__2022-05-02T18:00:00+00:00 [queued]>
[2022-05-02 22:30:29,284] {taskinstance.py:1032} INFO - Dependencies all met for <TaskInstance: ETL.main scheduled__2022-05-02T18:00:00+00:00 [queued]>
[2022-05-02 22:30:29,287] {taskinstance.py:1238} INFO - 
--------------------------------------------------------------------------------
[2022-05-02 22:30:29,289] {taskinstance.py:1239} INFO - Starting attempt 5 of 6
[2022-05-02 22:30:29,291] {taskinstance.py:1240} INFO - 
--------------------------------------------------------------------------------
[2022-05-02 22:30:29,374] {taskinstance.py:1259} INFO - Executing <Task(PythonOperator): main> on 2022-05-02 18:00:00+00:00
[2022-05-02 22:30:29,400] {standard_task_runner.py:52} INFO - Started process 1000 to run task
[2022-05-02 22:30:29,437] {standard_task_runner.py:76} INFO - Running: ['***', 'tasks', 'run', 'ETL', 'main', 'scheduled__2022-05-02T18:00:00+00:00', '--job-id', '6', '--raw', '--subdir', 'DAGS_FOLDER/ETL.py', '--cfg-path', '/tmp/tmp2irf9i_m', '--error-file', '/tmp/tmpo627toa6']
[2022-05-02 22:30:29,441] {standard_task_runner.py:77} INFO - Job 6: Subtask main
[2022-05-02 22:30:29,634] {logging_mixin.py:109} INFO - Running <TaskInstance: ETL.main scheduled__2022-05-02T18:00:00+00:00 [running]> on host 9f1b8837587a
[2022-05-02 22:30:29,786] {taskinstance.py:1426} INFO - Exporting the following env vars:
AIRFLOW_CTX_DAG_OWNER=***
AIRFLOW_CTX_DAG_ID=ETL
AIRFLOW_CTX_TASK_ID=main
AIRFLOW_CTX_EXECUTION_DATE=2022-05-02T18:00:00+00:00
AIRFLOW_CTX_DAG_RUN_ID=scheduled__2022-05-02T18:00:00+00:00
[2022-05-02 22:30:30,145] {logging_mixin.py:109} INFO - ['BTC/USD', '2022-05-02 22:30:29', 38977.85]
[2022-05-02 22:30:30,153] {logging_mixin.py:109} INFO - etl does not exist in the DB!
[2022-05-02 22:30:30,156] {taskinstance.py:1700} ERROR - Task failed with exception
Traceback (most recent call last):
  File "/home/airflow/.local/lib/python3.7/site-packages/airflow/models/taskinstance.py", line 1329, in _run_raw_task
    self._execute_task_with_callbacks(context)
  File "/home/airflow/.local/lib/python3.7/site-packages/airflow/models/taskinstance.py", line 1455, in _execute_task_with_callbacks
    result = self._execute_task(context, self.task)
  File "/home/airflow/.local/lib/python3.7/site-packages/airflow/models/taskinstance.py", line 1511, in _execute_task
    result = execute_callable(context=context)
  File "/home/airflow/.local/lib/python3.7/site-packages/airflow/operators/python.py", line 174, in execute
    return_value = self.execute_callable()
  File "/home/airflow/.local/lib/python3.7/site-packages/airflow/operators/python.py", line 185, in execute_callable
    return self.python_callable(*self.op_args, **self.op_kwargs)
  File "/opt/airflow/dags/ETL.py", line 65, in main
    check_table_exists("etl", engine)
  File "/opt/airflow/dags/ETL.py", line 27, in check_table_exists
    pd.read_sql(f"CREATE TABLE currnecy.""{table_name}"" (currency_pair VARCHAR NOT NULL,    created_on TIMESTAMP NOT NULL, current_rate decimal not null );")
TypeError: read_sql() missing 1 required positional argument: 'con'
[2022-05-02 22:30:30,201] {taskinstance.py:1277} INFO - Marking task as UP_FOR_RETRY. dag_id=ETL, task_id=main, execution_date=20220502T180000, start_date=20220502T223029, end_date=20220502T223030
[2022-05-02 22:30:30,262] {standard_task_runner.py:92} ERROR - Failed to execute job 6 for task main
Traceback (most recent call last):
  File "/home/airflow/.local/lib/python3.7/site-packages/airflow/task/task_runner/standard_task_runner.py", line 85, in _start_by_fork
    args.func(args, dag=self.dag)
  File "/home/airflow/.local/lib/python3.7/site-packages/airflow/cli/cli_parser.py", line 48, in command
    return func(*args, **kwargs)
  File "/home/airflow/.local/lib/python3.7/site-packages/airflow/utils/cli.py", line 92, in wrapper
    return f(*args, **kwargs)
  File "/home/airflow/.local/lib/python3.7/site-packages/airflow/cli/commands/task_command.py", line 298, in task_run
    _run_task_by_selected_method(args, dag, ti)
  File "/home/airflow/.local/lib/python3.7/site-packages/airflow/cli/commands/task_command.py", line 107, in _run_task_by_selected_method
    _run_raw_task(args, ti)
  File "/home/airflow/.local/lib/python3.7/site-packages/airflow/cli/commands/task_command.py", line 184, in _run_raw_task
    error_file=args.error_file,
  File "/home/airflow/.local/lib/python3.7/site-packages/airflow/utils/session.py", line 70, in wrapper
    return func(*args, session=session, **kwargs)
  File "/home/airflow/.local/lib/python3.7/site-packages/airflow/models/taskinstance.py", line 1329, in _run_raw_task
    self._execute_task_with_callbacks(context)
  File "/home/airflow/.local/lib/python3.7/site-packages/airflow/models/taskinstance.py", line 1455, in _execute_task_with_callbacks
    result = self._execute_task(context, self.task)
  File "/home/airflow/.local/lib/python3.7/site-packages/airflow/models/taskinstance.py", line 1511, in _execute_task
    result = execute_callable(context=context)
  File "/home/airflow/.local/lib/python3.7/site-packages/airflow/operators/python.py", line 174, in execute
    return_value = self.execute_callable()
  File "/home/airflow/.local/lib/python3.7/site-packages/airflow/operators/python.py", line 185, in execute_callable
    return self.python_callable(*self.op_args, **self.op_kwargs)
  File "/opt/airflow/dags/ETL.py", line 65, in main
    check_table_exists("etl", engine)
  File "/opt/airflow/dags/ETL.py", line 27, in check_table_exists
    pd.read_sql(f"CREATE TABLE currnecy.""{table_name}"" (currency_pair VARCHAR NOT NULL,    created_on TIMESTAMP NOT NULL, current_rate decimal not null );")
TypeError: read_sql() missing 1 required positional argument: 'con'
[2022-05-02 22:30:30,299] {local_task_job.py:154} INFO - Task exited with return code 1
[2022-05-02 22:30:30,442] {local_task_job.py:264} INFO - 0 downstream tasks scheduled from follow-on schedule check
