[2022-05-02 22:41:59,090] {taskinstance.py:1032} INFO - Dependencies all met for <TaskInstance: ETL.main scheduled__2022-05-02T18:00:00+00:00 [queued]>
[2022-05-02 22:41:59,146] {taskinstance.py:1032} INFO - Dependencies all met for <TaskInstance: ETL.main scheduled__2022-05-02T18:00:00+00:00 [queued]>
[2022-05-02 22:41:59,148] {taskinstance.py:1238} INFO - 
--------------------------------------------------------------------------------
[2022-05-02 22:41:59,151] {taskinstance.py:1239} INFO - Starting attempt 9 of 10
[2022-05-02 22:41:59,153] {taskinstance.py:1240} INFO - 
--------------------------------------------------------------------------------
[2022-05-02 22:41:59,196] {taskinstance.py:1259} INFO - Executing <Task(PythonOperator): main> on 2022-05-02 18:00:00+00:00
[2022-05-02 22:41:59,206] {standard_task_runner.py:52} INFO - Started process 1617 to run task
[2022-05-02 22:41:59,215] {standard_task_runner.py:76} INFO - Running: ['***', 'tasks', 'run', 'ETL', 'main', 'scheduled__2022-05-02T18:00:00+00:00', '--job-id', '10', '--raw', '--subdir', 'DAGS_FOLDER/ETL.py', '--cfg-path', '/tmp/tmpllltts53', '--error-file', '/tmp/tmpqm2bsuca']
[2022-05-02 22:41:59,218] {standard_task_runner.py:77} INFO - Job 10: Subtask main
[2022-05-02 22:41:59,371] {logging_mixin.py:109} INFO - Running <TaskInstance: ETL.main scheduled__2022-05-02T18:00:00+00:00 [running]> on host 9f1b8837587a
[2022-05-02 22:41:59,528] {taskinstance.py:1426} INFO - Exporting the following env vars:
AIRFLOW_CTX_DAG_OWNER=***
AIRFLOW_CTX_DAG_ID=ETL
AIRFLOW_CTX_TASK_ID=main
AIRFLOW_CTX_EXECUTION_DATE=2022-05-02T18:00:00+00:00
AIRFLOW_CTX_DAG_RUN_ID=scheduled__2022-05-02T18:00:00+00:00
[2022-05-02 22:41:59,891] {logging_mixin.py:109} INFO - ['BTC/USD', '2022-05-02 22:41:59', 38957.7]
[2022-05-02 22:41:59,900] {logging_mixin.py:109} INFO - 'etl' exists in the DB!
[2022-05-02 22:41:59,902] {taskinstance.py:1700} ERROR - Task failed with exception
Traceback (most recent call last):
  File "/home/airflow/.local/lib/python3.7/site-packages/airflow/models/taskinstance.py", line 1329, in _run_raw_task
    self._execute_task_with_callbacks(context)
  File "/home/airflow/.local/lib/python3.7/site-packages/airflow/models/taskinstance.py", line 1455, in _execute_task_with_callbacks
    result = self._execute_task(context, self.task)
  File "/home/airflow/.local/lib/python3.7/site-packages/airflow/models/taskinstance.py", line 1511, in _execute_task
    result = execute_callable(context=context)
  File "/home/airflow/.local/lib/python3.7/site-packages/airflow/operators/python.py", line 174, in execute
    return_value = self.execute_callable()
  File "/home/airflow/.local/lib/python3.7/site-packages/airflow/operators/python.py", line 185, in execute_callable
    return self.python_callable(*self.op_args, **self.op_kwargs)
  File "/opt/airflow/dags/ETL.py", line 65, in main
    check_table_exists("etl", engine)
  File "/opt/airflow/dags/ETL.py", line 22, in check_table_exists
    pd.read_sql((f"INSERT into {table_name} (currency_pair, created_on, current_rate) VALUES (%s, %s, %s)", listToPg), engine)
NameError: name 'listToPg' is not defined
[2022-05-02 22:41:59,944] {taskinstance.py:1277} INFO - Marking task as UP_FOR_RETRY. dag_id=ETL, task_id=main, execution_date=20220502T180000, start_date=20220502T224159, end_date=20220502T224159
[2022-05-02 22:41:59,998] {standard_task_runner.py:92} ERROR - Failed to execute job 10 for task main
Traceback (most recent call last):
  File "/home/airflow/.local/lib/python3.7/site-packages/airflow/task/task_runner/standard_task_runner.py", line 85, in _start_by_fork
    args.func(args, dag=self.dag)
  File "/home/airflow/.local/lib/python3.7/site-packages/airflow/cli/cli_parser.py", line 48, in command
    return func(*args, **kwargs)
  File "/home/airflow/.local/lib/python3.7/site-packages/airflow/utils/cli.py", line 92, in wrapper
    return f(*args, **kwargs)
  File "/home/airflow/.local/lib/python3.7/site-packages/airflow/cli/commands/task_command.py", line 298, in task_run
    _run_task_by_selected_method(args, dag, ti)
  File "/home/airflow/.local/lib/python3.7/site-packages/airflow/cli/commands/task_command.py", line 107, in _run_task_by_selected_method
    _run_raw_task(args, ti)
  File "/home/airflow/.local/lib/python3.7/site-packages/airflow/cli/commands/task_command.py", line 184, in _run_raw_task
    error_file=args.error_file,
  File "/home/airflow/.local/lib/python3.7/site-packages/airflow/utils/session.py", line 70, in wrapper
    return func(*args, session=session, **kwargs)
  File "/home/airflow/.local/lib/python3.7/site-packages/airflow/models/taskinstance.py", line 1329, in _run_raw_task
    self._execute_task_with_callbacks(context)
  File "/home/airflow/.local/lib/python3.7/site-packages/airflow/models/taskinstance.py", line 1455, in _execute_task_with_callbacks
    result = self._execute_task(context, self.task)
  File "/home/airflow/.local/lib/python3.7/site-packages/airflow/models/taskinstance.py", line 1511, in _execute_task
    result = execute_callable(context=context)
  File "/home/airflow/.local/lib/python3.7/site-packages/airflow/operators/python.py", line 174, in execute
    return_value = self.execute_callable()
  File "/home/airflow/.local/lib/python3.7/site-packages/airflow/operators/python.py", line 185, in execute_callable
    return self.python_callable(*self.op_args, **self.op_kwargs)
  File "/opt/airflow/dags/ETL.py", line 65, in main
    check_table_exists("etl", engine)
  File "/opt/airflow/dags/ETL.py", line 22, in check_table_exists
    pd.read_sql((f"INSERT into {table_name} (currency_pair, created_on, current_rate) VALUES (%s, %s, %s)", listToPg), engine)
NameError: name 'listToPg' is not defined
[2022-05-02 22:42:00,046] {local_task_job.py:154} INFO - Task exited with return code 1
[2022-05-02 22:42:00,173] {local_task_job.py:264} INFO - 0 downstream tasks scheduled from follow-on schedule check
